2023-05-04 18:58:07.990 [info] Extension host with pid 4079967 started
2023-05-04 18:58:07.990 [info] Skipping acquiring lock for /home/nicklas/.config/Code/User/workspaceStorage/c9eea337a93387978f23d9d4dfb59b64.
2023-05-04 18:58:08.092 [info] ExtensionService#_doActivateExtension vscode.emmet, startup: false, activationEvent: 'onLanguage'
2023-05-04 18:58:08.099 [info] ExtensionService#_doActivateExtension ms-python.python, startup: false, activationEvent: 'onLanguage:python', root cause: ms-python.isort
2023-05-04 18:58:08.144 [info] ExtensionService#_doActivateExtension ms-toolsai.jupyter, startup: false, activationEvent: 'onLanguage:python'
2023-05-04 18:58:08.203 [info] Extension host with pid 4080138 started
2023-05-04 18:58:08.203 [info] Skipping acquiring lock for /home/nicklas/.config/Code/User/workspaceStorage/c9eea337a93387978f23d9d4dfb59b64.
2023-05-04 18:58:08.347 [info] ExtensionService#_doActivateExtension asvetliakov.vscode-neovim, startup: true, activationEvent: '*'
2023-05-04 18:58:08.387 [info] ExtensionService#_doActivateExtension ms-toolsai.jupyter-renderers, startup: false, activationEvent: 'api', root cause: ms-toolsai.jupyter
2023-05-04 18:58:08.522 [info] ExtensionService#_doActivateExtension ms-python.isort, startup: false, activationEvent: 'onLanguage:python'
2023-05-04 18:58:08.536 [info] ExtensionService#_doActivateExtension ms-python.vscode-pylance, startup: false, activationEvent: 'onLanguage:python'
2023-05-04 18:58:08.626 [info] Eager extensions activated
2023-05-04 18:58:08.934 [info] ExtensionService#_doActivateExtension vscode.git-base, startup: true, activationEvent: '*', root cause: vscode.git
2023-05-04 18:58:08.952 [info] ExtensionService#_doActivateExtension vscode.git, startup: true, activationEvent: '*'
2023-05-04 18:58:08.980 [info] ExtensionService#_doActivateExtension vscode.github, startup: true, activationEvent: '*'
2023-05-04 18:58:09.016 [info] Eager extensions activated
2023-05-04 18:58:09.056 [info] ExtensionService#_doActivateExtension vscode.debug-auto-launch, startup: false, activationEvent: 'onStartupFinished'
2023-05-04 18:58:09.058 [info] ExtensionService#_doActivateExtension vscode.merge-conflict, startup: false, activationEvent: 'onStartupFinished'
2023-05-04 18:58:09.062 [info] ExtensionService#_doActivateExtension ExodiusStudios.comment-anchors, startup: false, activationEvent: 'onStartupFinished'
2023-05-04 18:58:09.083 [info] ExtensionService#_doActivateExtension GitHub.copilot, startup: false, activationEvent: 'onStartupFinished'
2023-05-04 18:58:09.175 [info] ExtensionService#_doActivateExtension GitHub.copilot-labs, startup: false, activationEvent: 'onStartupFinished'
2023-05-04 18:58:09.383 [info] ExtensionService#_doActivateExtension vscode.github-authentication, startup: false, activationEvent: 'onAuthenticationRequest:github'
2023-05-04 18:58:09.494 [info] ExtensionService#_doActivateExtension vscode.microsoft-authentication, startup: false, activationEvent: 'onAuthenticationRequest:microsoft'
2023-05-04 18:58:10.632 [info] ExtensionService#_doActivateExtension vscode.configuration-editing, startup: false, activationEvent: 'onLanguage:jsonc'
2023-05-04 18:58:10.635 [info] ExtensionService#_doActivateExtension vscode.json-language-features, startup: false, activationEvent: 'onLanguage:jsonc'
2023-05-04 18:58:10.645 [info] ExtensionService#_doActivateExtension vscode.typescript-language-features, startup: false, activationEvent: 'onLanguage:jsonc'
2023-05-04 18:58:54.612 [error] Error: Traceback (most recent call last):
  File "/home/nicklas/.vscode/extensions/ms-python.python-2023.6.1/pythonFiles/get_output_via_markers.py", line 26, in <module>
    runpy.run_path(module, run_name="__main__")
  File "/home/nicklas/mambaforge/envs/math/lib/python3.8/runpy.py", line 265, in run_path
    return _run_module_code(code, init_globals, run_name,
  File "/home/nicklas/mambaforge/envs/math/lib/python3.8/runpy.py", line 97, in _run_module_code
    _run_code(code, mod_globals, init_globals,
  File "/home/nicklas/mambaforge/envs/math/lib/python3.8/runpy.py", line 87, in _run_code
    exec(code, run_globals)
  File "/home/nicklas/.vscode/extensions/ms-python.python-2023.6.1/pythonFiles/testing_tools/run_adapter.py", line 17, in <module>
    from testing_tools.adapter.__main__ import parse_args, main
  File "/home/nicklas/.vscode/extensions/ms-python.python-2023.6.1/pythonFiles/testing_tools/adapter/__main__.py", line 9, in <module>
    from . import pytest, report
  File "/home/nicklas/.vscode/extensions/ms-python.python-2023.6.1/pythonFiles/testing_tools/adapter/pytest/__init__.py", line 7, in <module>
    from ._discovery import discover
  File "/home/nicklas/.vscode/extensions/ms-python.python-2023.6.1/pythonFiles/testing_tools/adapter/pytest/_discovery.py", line 8, in <module>
    import pytest
ModuleNotFoundError: No module named 'pytest'
ERROR conda.cli.main_run:execute(49): `conda run python /home/nicklas/.vscode/extensions/ms-python.python-2023.6.1/pythonFiles/get_output_via_markers.py /home/nicklas/.vscode/extensions/ms-python.python-2023.6.1/pythonFiles/testing_tools/run_adapter.py discover pytest -- --rootdir /home/nicklas/Projects/maxscience -s --cache-clear` failed. (See above for error)

    at ChildProcess.<anonymous> (/home/nicklas/.vscode/extensions/ms-python.python-2023.6.1/out/client/extension.js:2:238829)
    at Object.onceWrapper (node:events:646:26)
    at ChildProcess.emit (node:events:526:28)
    at maybeClose (node:internal/child_process:1092:16)
    at Process.ChildProcess._handle.onexit (node:internal/child_process:302:5)
2023-05-04 18:58:55.492 [error] Error: Traceback (most recent call last):
  File "/home/nicklas/.vscode/extensions/ms-python.python-2023.6.1/pythonFiles/get_output_via_markers.py", line 26, in <module>
    runpy.run_path(module, run_name="__main__")
  File "/home/nicklas/mambaforge/envs/math/lib/python3.8/runpy.py", line 265, in run_path
    return _run_module_code(code, init_globals, run_name,
  File "/home/nicklas/mambaforge/envs/math/lib/python3.8/runpy.py", line 97, in _run_module_code
    _run_code(code, mod_globals, init_globals,
  File "/home/nicklas/mambaforge/envs/math/lib/python3.8/runpy.py", line 87, in _run_code
    exec(code, run_globals)
  File "/home/nicklas/.vscode/extensions/ms-python.python-2023.6.1/pythonFiles/testing_tools/run_adapter.py", line 17, in <module>
    from testing_tools.adapter.__main__ import parse_args, main
  File "/home/nicklas/.vscode/extensions/ms-python.python-2023.6.1/pythonFiles/testing_tools/adapter/__main__.py", line 9, in <module>
    from . import pytest, report
  File "/home/nicklas/.vscode/extensions/ms-python.python-2023.6.1/pythonFiles/testing_tools/adapter/pytest/__init__.py", line 7, in <module>
    from ._discovery import discover
  File "/home/nicklas/.vscode/extensions/ms-python.python-2023.6.1/pythonFiles/testing_tools/adapter/pytest/_discovery.py", line 8, in <module>
    import pytest
ModuleNotFoundError: No module named 'pytest'
ERROR conda.cli.main_run:execute(49): `conda run python /home/nicklas/.vscode/extensions/ms-python.python-2023.6.1/pythonFiles/get_output_via_markers.py /home/nicklas/.vscode/extensions/ms-python.python-2023.6.1/pythonFiles/testing_tools/run_adapter.py discover pytest -- --rootdir /home/nicklas/Projects/maxscience -s --cache-clear` failed. (See above for error)

    at ChildProcess.<anonymous> (/home/nicklas/.vscode/extensions/ms-python.python-2023.6.1/out/client/extension.js:2:238829)
    at Object.onceWrapper (node:events:646:26)
    at ChildProcess.emit (node:events:526:28)
    at maybeClose (node:internal/child_process:1092:16)
    at Socket.<anonymous> (node:internal/child_process:451:11)
    at Socket.emit (node:events:526:28)
    at Pipe.<anonymous> (node:net:687:12)
2023-05-04 18:59:51.734 [error] Error: Traceback (most recent call last):
  File "/home/nicklas/.vscode/extensions/ms-python.python-2023.6.1/pythonFiles/get_output_via_markers.py", line 26, in <module>
    runpy.run_path(module, run_name="__main__")
  File "/home/nicklas/mambaforge/envs/math/lib/python3.8/runpy.py", line 265, in run_path
    return _run_module_code(code, init_globals, run_name,
  File "/home/nicklas/mambaforge/envs/math/lib/python3.8/runpy.py", line 97, in _run_module_code
    _run_code(code, mod_globals, init_globals,
  File "/home/nicklas/mambaforge/envs/math/lib/python3.8/runpy.py", line 87, in _run_code
    exec(code, run_globals)
  File "/home/nicklas/.vscode/extensions/ms-python.python-2023.6.1/pythonFiles/testing_tools/run_adapter.py", line 17, in <module>
    from testing_tools.adapter.__main__ import parse_args, main
  File "/home/nicklas/.vscode/extensions/ms-python.python-2023.6.1/pythonFiles/testing_tools/adapter/__main__.py", line 9, in <module>
    from . import pytest, report
  File "/home/nicklas/.vscode/extensions/ms-python.python-2023.6.1/pythonFiles/testing_tools/adapter/pytest/__init__.py", line 7, in <module>
    from ._discovery import discover
  File "/home/nicklas/.vscode/extensions/ms-python.python-2023.6.1/pythonFiles/testing_tools/adapter/pytest/_discovery.py", line 8, in <module>
    import pytest
ModuleNotFoundError: No module named 'pytest'
ERROR conda.cli.main_run:execute(49): `conda run python /home/nicklas/.vscode/extensions/ms-python.python-2023.6.1/pythonFiles/get_output_via_markers.py /home/nicklas/.vscode/extensions/ms-python.python-2023.6.1/pythonFiles/testing_tools/run_adapter.py discover pytest -- --rootdir /home/nicklas/Projects/maxscience -s --cache-clear` failed. (See above for error)

    at ChildProcess.<anonymous> (/home/nicklas/.vscode/extensions/ms-python.python-2023.6.1/out/client/extension.js:2:238829)
    at Object.onceWrapper (node:events:646:26)
    at ChildProcess.emit (node:events:526:28)
    at maybeClose (node:internal/child_process:1092:16)
    at Socket.<anonymous> (node:internal/child_process:451:11)
    at Socket.emit (node:events:526:28)
    at Pipe.<anonymous> (node:net:687:12)
2023-05-04 18:59:54.219 [error] Error: Traceback (most recent call last):
  File "/home/nicklas/.vscode/extensions/ms-python.python-2023.6.1/pythonFiles/get_output_via_markers.py", line 26, in <module>
    runpy.run_path(module, run_name="__main__")
  File "/home/nicklas/mambaforge/envs/math/lib/python3.8/runpy.py", line 265, in run_path
    return _run_module_code(code, init_globals, run_name,
  File "/home/nicklas/mambaforge/envs/math/lib/python3.8/runpy.py", line 97, in _run_module_code
    _run_code(code, mod_globals, init_globals,
  File "/home/nicklas/mambaforge/envs/math/lib/python3.8/runpy.py", line 87, in _run_code
    exec(code, run_globals)
  File "/home/nicklas/.vscode/extensions/ms-python.python-2023.6.1/pythonFiles/testing_tools/run_adapter.py", line 17, in <module>
    from testing_tools.adapter.__main__ import parse_args, main
  File "/home/nicklas/.vscode/extensions/ms-python.python-2023.6.1/pythonFiles/testing_tools/adapter/__main__.py", line 9, in <module>
    from . import pytest, report
  File "/home/nicklas/.vscode/extensions/ms-python.python-2023.6.1/pythonFiles/testing_tools/adapter/pytest/__init__.py", line 7, in <module>
    from ._discovery import discover
  File "/home/nicklas/.vscode/extensions/ms-python.python-2023.6.1/pythonFiles/testing_tools/adapter/pytest/_discovery.py", line 8, in <module>
    import pytest
ModuleNotFoundError: No module named 'pytest'
ERROR conda.cli.main_run:execute(49): `conda run python /home/nicklas/.vscode/extensions/ms-python.python-2023.6.1/pythonFiles/get_output_via_markers.py /home/nicklas/.vscode/extensions/ms-python.python-2023.6.1/pythonFiles/testing_tools/run_adapter.py discover pytest -- --rootdir /home/nicklas/Projects/maxscience -s --cache-clear` failed. (See above for error)

    at ChildProcess.<anonymous> (/home/nicklas/.vscode/extensions/ms-python.python-2023.6.1/out/client/extension.js:2:238829)
    at Object.onceWrapper (node:events:646:26)
    at ChildProcess.emit (node:events:526:28)
    at maybeClose (node:internal/child_process:1092:16)
    at Socket.<anonymous> (node:internal/child_process:451:11)
    at Socket.emit (node:events:526:28)
    at Pipe.<anonymous> (node:net:687:12)
2023-05-04 18:59:55.504 [info] ExtensionService#_doActivateExtension cweijan.vscode-autohotkey-plus, startup: false, activationEvent: 'onDebug'
2023-05-04 18:59:55.540 [info] ExtensionService#_doActivateExtension vscode.debug-server-ready, startup: false, activationEvent: 'onDebugResolve'
2023-05-04 18:59:55.959 [error] Error: Traceback (most recent call last):
  File "/home/nicklas/.vscode/extensions/ms-python.python-2023.6.1/pythonFiles/get_output_via_markers.py", line 26, in <module>
    runpy.run_path(module, run_name="__main__")
  File "/home/nicklas/mambaforge/envs/math/lib/python3.8/runpy.py", line 265, in run_path
    return _run_module_code(code, init_globals, run_name,
  File "/home/nicklas/mambaforge/envs/math/lib/python3.8/runpy.py", line 97, in _run_module_code
    _run_code(code, mod_globals, init_globals,
  File "/home/nicklas/mambaforge/envs/math/lib/python3.8/runpy.py", line 87, in _run_code
    exec(code, run_globals)
  File "/home/nicklas/.vscode/extensions/ms-python.python-2023.6.1/pythonFiles/testing_tools/run_adapter.py", line 17, in <module>
    from testing_tools.adapter.__main__ import parse_args, main
  File "/home/nicklas/.vscode/extensions/ms-python.python-2023.6.1/pythonFiles/testing_tools/adapter/__main__.py", line 9, in <module>
    from . import pytest, report
  File "/home/nicklas/.vscode/extensions/ms-python.python-2023.6.1/pythonFiles/testing_tools/adapter/pytest/__init__.py", line 7, in <module>
    from ._discovery import discover
  File "/home/nicklas/.vscode/extensions/ms-python.python-2023.6.1/pythonFiles/testing_tools/adapter/pytest/_discovery.py", line 8, in <module>
    import pytest
ModuleNotFoundError: No module named 'pytest'
ERROR conda.cli.main_run:execute(49): `conda run python /home/nicklas/.vscode/extensions/ms-python.python-2023.6.1/pythonFiles/get_output_via_markers.py /home/nicklas/.vscode/extensions/ms-python.python-2023.6.1/pythonFiles/testing_tools/run_adapter.py discover pytest -- --rootdir /home/nicklas/Projects/maxscience -s --cache-clear` failed. (See above for error)

    at ChildProcess.<anonymous> (/home/nicklas/.vscode/extensions/ms-python.python-2023.6.1/out/client/extension.js:2:238829)
    at Object.onceWrapper (node:events:646:26)
    at ChildProcess.emit (node:events:526:28)
    at maybeClose (node:internal/child_process:1092:16)
    at Process.ChildProcess._handle.onexit (node:internal/child_process:302:5)
2023-05-04 19:00:02.884 [error] Error: Traceback (most recent call last):
  File "/home/nicklas/.vscode/extensions/ms-python.python-2023.6.1/pythonFiles/get_output_via_markers.py", line 26, in <module>
    runpy.run_path(module, run_name="__main__")
  File "/home/nicklas/mambaforge/envs/math/lib/python3.8/runpy.py", line 265, in run_path
    return _run_module_code(code, init_globals, run_name,
  File "/home/nicklas/mambaforge/envs/math/lib/python3.8/runpy.py", line 97, in _run_module_code
    _run_code(code, mod_globals, init_globals,
  File "/home/nicklas/mambaforge/envs/math/lib/python3.8/runpy.py", line 87, in _run_code
    exec(code, run_globals)
  File "/home/nicklas/.vscode/extensions/ms-python.python-2023.6.1/pythonFiles/testing_tools/run_adapter.py", line 17, in <module>
    from testing_tools.adapter.__main__ import parse_args, main
  File "/home/nicklas/.vscode/extensions/ms-python.python-2023.6.1/pythonFiles/testing_tools/adapter/__main__.py", line 9, in <module>
    from . import pytest, report
  File "/home/nicklas/.vscode/extensions/ms-python.python-2023.6.1/pythonFiles/testing_tools/adapter/pytest/__init__.py", line 7, in <module>
    from ._discovery import discover
  File "/home/nicklas/.vscode/extensions/ms-python.python-2023.6.1/pythonFiles/testing_tools/adapter/pytest/_discovery.py", line 8, in <module>
    import pytest
ModuleNotFoundError: No module named 'pytest'
ERROR conda.cli.main_run:execute(49): `conda run python /home/nicklas/.vscode/extensions/ms-python.python-2023.6.1/pythonFiles/get_output_via_markers.py /home/nicklas/.vscode/extensions/ms-python.python-2023.6.1/pythonFiles/testing_tools/run_adapter.py discover pytest -- --rootdir /home/nicklas/Projects/maxscience -s --cache-clear` failed. (See above for error)

    at ChildProcess.<anonymous> (/home/nicklas/.vscode/extensions/ms-python.python-2023.6.1/out/client/extension.js:2:238829)
    at Object.onceWrapper (node:events:646:26)
    at ChildProcess.emit (node:events:526:28)
    at maybeClose (node:internal/child_process:1092:16)
    at Socket.<anonymous> (node:internal/child_process:451:11)
    at Socket.emit (node:events:526:28)
    at Pipe.<anonymous> (node:net:687:12)
2023-05-04 19:00:05.032 [error] Error: Traceback (most recent call last):
  File "/home/nicklas/.vscode/extensions/ms-python.python-2023.6.1/pythonFiles/get_output_via_markers.py", line 26, in <module>
    runpy.run_path(module, run_name="__main__")
  File "/home/nicklas/mambaforge/envs/math/lib/python3.8/runpy.py", line 265, in run_path
    return _run_module_code(code, init_globals, run_name,
  File "/home/nicklas/mambaforge/envs/math/lib/python3.8/runpy.py", line 97, in _run_module_code
    _run_code(code, mod_globals, init_globals,
  File "/home/nicklas/mambaforge/envs/math/lib/python3.8/runpy.py", line 87, in _run_code
    exec(code, run_globals)
  File "/home/nicklas/.vscode/extensions/ms-python.python-2023.6.1/pythonFiles/testing_tools/run_adapter.py", line 17, in <module>
    from testing_tools.adapter.__main__ import parse_args, main
  File "/home/nicklas/.vscode/extensions/ms-python.python-2023.6.1/pythonFiles/testing_tools/adapter/__main__.py", line 9, in <module>
    from . import pytest, report
  File "/home/nicklas/.vscode/extensions/ms-python.python-2023.6.1/pythonFiles/testing_tools/adapter/pytest/__init__.py", line 7, in <module>
    from ._discovery import discover
  File "/home/nicklas/.vscode/extensions/ms-python.python-2023.6.1/pythonFiles/testing_tools/adapter/pytest/_discovery.py", line 8, in <module>
    import pytest
ModuleNotFoundError: No module named 'pytest'
ERROR conda.cli.main_run:execute(49): `conda run python /home/nicklas/.vscode/extensions/ms-python.python-2023.6.1/pythonFiles/get_output_via_markers.py /home/nicklas/.vscode/extensions/ms-python.python-2023.6.1/pythonFiles/testing_tools/run_adapter.py discover pytest -- --rootdir /home/nicklas/Projects/maxscience -s --cache-clear` failed. (See above for error)

    at ChildProcess.<anonymous> (/home/nicklas/.vscode/extensions/ms-python.python-2023.6.1/out/client/extension.js:2:238829)
    at Object.onceWrapper (node:events:646:26)
    at ChildProcess.emit (node:events:526:28)
    at maybeClose (node:internal/child_process:1092:16)
    at Socket.<anonymous> (node:internal/child_process:451:11)
    at Socket.emit (node:events:526:28)
    at Pipe.<anonymous> (node:net:687:12)
2023-05-04 19:00:09.328 [error] Error: Traceback (most recent call last):
  File "/home/nicklas/.vscode/extensions/ms-python.python-2023.6.1/pythonFiles/get_output_via_markers.py", line 26, in <module>
    runpy.run_path(module, run_name="__main__")
  File "/home/nicklas/mambaforge/envs/math/lib/python3.8/runpy.py", line 265, in run_path
    return _run_module_code(code, init_globals, run_name,
  File "/home/nicklas/mambaforge/envs/math/lib/python3.8/runpy.py", line 97, in _run_module_code
    _run_code(code, mod_globals, init_globals,
  File "/home/nicklas/mambaforge/envs/math/lib/python3.8/runpy.py", line 87, in _run_code
    exec(code, run_globals)
  File "/home/nicklas/.vscode/extensions/ms-python.python-2023.6.1/pythonFiles/testing_tools/run_adapter.py", line 17, in <module>
    from testing_tools.adapter.__main__ import parse_args, main
  File "/home/nicklas/.vscode/extensions/ms-python.python-2023.6.1/pythonFiles/testing_tools/adapter/__main__.py", line 9, in <module>
    from . import pytest, report
  File "/home/nicklas/.vscode/extensions/ms-python.python-2023.6.1/pythonFiles/testing_tools/adapter/pytest/__init__.py", line 7, in <module>
    from ._discovery import discover
  File "/home/nicklas/.vscode/extensions/ms-python.python-2023.6.1/pythonFiles/testing_tools/adapter/pytest/_discovery.py", line 8, in <module>
    import pytest
ModuleNotFoundError: No module named 'pytest'
ERROR conda.cli.main_run:execute(49): `conda run python /home/nicklas/.vscode/extensions/ms-python.python-2023.6.1/pythonFiles/get_output_via_markers.py /home/nicklas/.vscode/extensions/ms-python.python-2023.6.1/pythonFiles/testing_tools/run_adapter.py discover pytest -- --rootdir /home/nicklas/Projects/maxscience -s --cache-clear` failed. (See above for error)

    at ChildProcess.<anonymous> (/home/nicklas/.vscode/extensions/ms-python.python-2023.6.1/out/client/extension.js:2:238829)
    at Object.onceWrapper (node:events:646:26)
    at ChildProcess.emit (node:events:526:28)
    at maybeClose (node:internal/child_process:1092:16)
    at Socket.<anonymous> (node:internal/child_process:451:11)
    at Socket.emit (node:events:526:28)
    at Pipe.<anonymous> (node:net:687:12)
2023-05-04 19:00:12.480 [error] Error: Traceback (most recent call last):
  File "/home/nicklas/.vscode/extensions/ms-python.python-2023.6.1/pythonFiles/get_output_via_markers.py", line 26, in <module>
    runpy.run_path(module, run_name="__main__")
  File "/home/nicklas/mambaforge/envs/math/lib/python3.8/runpy.py", line 265, in run_path
    return _run_module_code(code, init_globals, run_name,
  File "/home/nicklas/mambaforge/envs/math/lib/python3.8/runpy.py", line 97, in _run_module_code
    _run_code(code, mod_globals, init_globals,
  File "/home/nicklas/mambaforge/envs/math/lib/python3.8/runpy.py", line 87, in _run_code
    exec(code, run_globals)
  File "/home/nicklas/.vscode/extensions/ms-python.python-2023.6.1/pythonFiles/testing_tools/run_adapter.py", line 17, in <module>
    from testing_tools.adapter.__main__ import parse_args, main
  File "/home/nicklas/.vscode/extensions/ms-python.python-2023.6.1/pythonFiles/testing_tools/adapter/__main__.py", line 9, in <module>
    from . import pytest, report
  File "/home/nicklas/.vscode/extensions/ms-python.python-2023.6.1/pythonFiles/testing_tools/adapter/pytest/__init__.py", line 7, in <module>
    from ._discovery import discover
  File "/home/nicklas/.vscode/extensions/ms-python.python-2023.6.1/pythonFiles/testing_tools/adapter/pytest/_discovery.py", line 8, in <module>
    import pytest
ModuleNotFoundError: No module named 'pytest'
ERROR conda.cli.main_run:execute(49): `conda run python /home/nicklas/.vscode/extensions/ms-python.python-2023.6.1/pythonFiles/get_output_via_markers.py /home/nicklas/.vscode/extensions/ms-python.python-2023.6.1/pythonFiles/testing_tools/run_adapter.py discover pytest -- --rootdir /home/nicklas/Projects/maxscience -s --cache-clear` failed. (See above for error)

    at ChildProcess.<anonymous> (/home/nicklas/.vscode/extensions/ms-python.python-2023.6.1/out/client/extension.js:2:238829)
    at Object.onceWrapper (node:events:646:26)
    at ChildProcess.emit (node:events:526:28)
    at maybeClose (node:internal/child_process:1092:16)
    at Socket.<anonymous> (node:internal/child_process:451:11)
    at Socket.emit (node:events:526:28)
    at Pipe.<anonymous> (node:net:687:12)
2023-05-04 19:00:15.418 [error] Error: Traceback (most recent call last):
  File "/home/nicklas/.vscode/extensions/ms-python.python-2023.6.1/pythonFiles/get_output_via_markers.py", line 26, in <module>
    runpy.run_path(module, run_name="__main__")
  File "/home/nicklas/mambaforge/envs/math/lib/python3.8/runpy.py", line 265, in run_path
    return _run_module_code(code, init_globals, run_name,
  File "/home/nicklas/mambaforge/envs/math/lib/python3.8/runpy.py", line 97, in _run_module_code
    _run_code(code, mod_globals, init_globals,
  File "/home/nicklas/mambaforge/envs/math/lib/python3.8/runpy.py", line 87, in _run_code
    exec(code, run_globals)
  File "/home/nicklas/.vscode/extensions/ms-python.python-2023.6.1/pythonFiles/testing_tools/run_adapter.py", line 17, in <module>
    from testing_tools.adapter.__main__ import parse_args, main
  File "/home/nicklas/.vscode/extensions/ms-python.python-2023.6.1/pythonFiles/testing_tools/adapter/__main__.py", line 9, in <module>
    from . import pytest, report
  File "/home/nicklas/.vscode/extensions/ms-python.python-2023.6.1/pythonFiles/testing_tools/adapter/pytest/__init__.py", line 7, in <module>
    from ._discovery import discover
  File "/home/nicklas/.vscode/extensions/ms-python.python-2023.6.1/pythonFiles/testing_tools/adapter/pytest/_discovery.py", line 8, in <module>
    import pytest
ModuleNotFoundError: No module named 'pytest'
ERROR conda.cli.main_run:execute(49): `conda run python /home/nicklas/.vscode/extensions/ms-python.python-2023.6.1/pythonFiles/get_output_via_markers.py /home/nicklas/.vscode/extensions/ms-python.python-2023.6.1/pythonFiles/testing_tools/run_adapter.py discover pytest -- --rootdir /home/nicklas/Projects/maxscience -s --cache-clear` failed. (See above for error)

    at ChildProcess.<anonymous> (/home/nicklas/.vscode/extensions/ms-python.python-2023.6.1/out/client/extension.js:2:238829)
    at Object.onceWrapper (node:events:646:26)
    at ChildProcess.emit (node:events:526:28)
    at maybeClose (node:internal/child_process:1092:16)
    at Socket.<anonymous> (node:internal/child_process:451:11)
    at Socket.emit (node:events:526:28)
    at Pipe.<anonymous> (node:net:687:12)
2023-05-04 19:00:23.091 [error] Error: Traceback (most recent call last):
  File "/home/nicklas/.vscode/extensions/ms-python.python-2023.6.1/pythonFiles/get_output_via_markers.py", line 26, in <module>
    runpy.run_path(module, run_name="__main__")
  File "/home/nicklas/mambaforge/envs/math/lib/python3.8/runpy.py", line 265, in run_path
    return _run_module_code(code, init_globals, run_name,
  File "/home/nicklas/mambaforge/envs/math/lib/python3.8/runpy.py", line 97, in _run_module_code
    _run_code(code, mod_globals, init_globals,
  File "/home/nicklas/mambaforge/envs/math/lib/python3.8/runpy.py", line 87, in _run_code
    exec(code, run_globals)
  File "/home/nicklas/.vscode/extensions/ms-python.python-2023.6.1/pythonFiles/testing_tools/run_adapter.py", line 17, in <module>
    from testing_tools.adapter.__main__ import parse_args, main
  File "/home/nicklas/.vscode/extensions/ms-python.python-2023.6.1/pythonFiles/testing_tools/adapter/__main__.py", line 9, in <module>
    from . import pytest, report
  File "/home/nicklas/.vscode/extensions/ms-python.python-2023.6.1/pythonFiles/testing_tools/adapter/pytest/__init__.py", line 7, in <module>
    from ._discovery import discover
  File "/home/nicklas/.vscode/extensions/ms-python.python-2023.6.1/pythonFiles/testing_tools/adapter/pytest/_discovery.py", line 8, in <module>
    import pytest
ModuleNotFoundError: No module named 'pytest'
ERROR conda.cli.main_run:execute(49): `conda run python /home/nicklas/.vscode/extensions/ms-python.python-2023.6.1/pythonFiles/get_output_via_markers.py /home/nicklas/.vscode/extensions/ms-python.python-2023.6.1/pythonFiles/testing_tools/run_adapter.py discover pytest -- --rootdir /home/nicklas/Projects/maxscience -s --cache-clear` failed. (See above for error)

    at ChildProcess.<anonymous> (/home/nicklas/.vscode/extensions/ms-python.python-2023.6.1/out/client/extension.js:2:238829)
    at Object.onceWrapper (node:events:646:26)
    at ChildProcess.emit (node:events:526:28)
    at maybeClose (node:internal/child_process:1092:16)
    at Process.ChildProcess._handle.onexit (node:internal/child_process:302:5)
2023-05-04 19:00:24.859 [error] Error: Traceback (most recent call last):
  File "/home/nicklas/.vscode/extensions/ms-python.python-2023.6.1/pythonFiles/get_output_via_markers.py", line 26, in <module>
    runpy.run_path(module, run_name="__main__")
  File "/home/nicklas/mambaforge/envs/math/lib/python3.8/runpy.py", line 265, in run_path
    return _run_module_code(code, init_globals, run_name,
  File "/home/nicklas/mambaforge/envs/math/lib/python3.8/runpy.py", line 97, in _run_module_code
    _run_code(code, mod_globals, init_globals,
  File "/home/nicklas/mambaforge/envs/math/lib/python3.8/runpy.py", line 87, in _run_code
    exec(code, run_globals)
  File "/home/nicklas/.vscode/extensions/ms-python.python-2023.6.1/pythonFiles/testing_tools/run_adapter.py", line 17, in <module>
    from testing_tools.adapter.__main__ import parse_args, main
  File "/home/nicklas/.vscode/extensions/ms-python.python-2023.6.1/pythonFiles/testing_tools/adapter/__main__.py", line 9, in <module>
    from . import pytest, report
  File "/home/nicklas/.vscode/extensions/ms-python.python-2023.6.1/pythonFiles/testing_tools/adapter/pytest/__init__.py", line 7, in <module>
    from ._discovery import discover
  File "/home/nicklas/.vscode/extensions/ms-python.python-2023.6.1/pythonFiles/testing_tools/adapter/pytest/_discovery.py", line 8, in <module>
    import pytest
ModuleNotFoundError: No module named 'pytest'
ERROR conda.cli.main_run:execute(49): `conda run python /home/nicklas/.vscode/extensions/ms-python.python-2023.6.1/pythonFiles/get_output_via_markers.py /home/nicklas/.vscode/extensions/ms-python.python-2023.6.1/pythonFiles/testing_tools/run_adapter.py discover pytest -- --rootdir /home/nicklas/Projects/maxscience -s --cache-clear` failed. (See above for error)

    at ChildProcess.<anonymous> (/home/nicklas/.vscode/extensions/ms-python.python-2023.6.1/out/client/extension.js:2:238829)
    at Object.onceWrapper (node:events:646:26)
    at ChildProcess.emit (node:events:526:28)
    at maybeClose (node:internal/child_process:1092:16)
    at Socket.<anonymous> (node:internal/child_process:451:11)
    at Socket.emit (node:events:526:28)
    at Pipe.<anonymous> (node:net:687:12)
2023-05-04 19:00:25.592 [error] Error: Traceback (most recent call last):
  File "/home/nicklas/.vscode/extensions/ms-python.python-2023.6.1/pythonFiles/get_output_via_markers.py", line 26, in <module>
    runpy.run_path(module, run_name="__main__")
  File "/home/nicklas/mambaforge/envs/math/lib/python3.8/runpy.py", line 265, in run_path
    return _run_module_code(code, init_globals, run_name,
  File "/home/nicklas/mambaforge/envs/math/lib/python3.8/runpy.py", line 97, in _run_module_code
    _run_code(code, mod_globals, init_globals,
  File "/home/nicklas/mambaforge/envs/math/lib/python3.8/runpy.py", line 87, in _run_code
    exec(code, run_globals)
  File "/home/nicklas/.vscode/extensions/ms-python.python-2023.6.1/pythonFiles/testing_tools/run_adapter.py", line 17, in <module>
    from testing_tools.adapter.__main__ import parse_args, main
  File "/home/nicklas/.vscode/extensions/ms-python.python-2023.6.1/pythonFiles/testing_tools/adapter/__main__.py", line 9, in <module>
    from . import pytest, report
  File "/home/nicklas/.vscode/extensions/ms-python.python-2023.6.1/pythonFiles/testing_tools/adapter/pytest/__init__.py", line 7, in <module>
    from ._discovery import discover
  File "/home/nicklas/.vscode/extensions/ms-python.python-2023.6.1/pythonFiles/testing_tools/adapter/pytest/_discovery.py", line 8, in <module>
    import pytest
ModuleNotFoundError: No module named 'pytest'
ERROR conda.cli.main_run:execute(49): `conda run python /home/nicklas/.vscode/extensions/ms-python.python-2023.6.1/pythonFiles/get_output_via_markers.py /home/nicklas/.vscode/extensions/ms-python.python-2023.6.1/pythonFiles/testing_tools/run_adapter.py discover pytest -- --rootdir /home/nicklas/Projects/maxscience -s --cache-clear` failed. (See above for error)

    at ChildProcess.<anonymous> (/home/nicklas/.vscode/extensions/ms-python.python-2023.6.1/out/client/extension.js:2:238829)
    at Object.onceWrapper (node:events:646:26)
    at ChildProcess.emit (node:events:526:28)
    at maybeClose (node:internal/child_process:1092:16)
    at Socket.<anonymous> (node:internal/child_process:451:11)
    at Socket.emit (node:events:526:28)
    at Pipe.<anonymous> (node:net:687:12)
2023-05-04 19:01:27.784 [error] Error: Traceback (most recent call last):
  File "/home/nicklas/.vscode/extensions/ms-python.python-2023.6.1/pythonFiles/get_output_via_markers.py", line 26, in <module>
    runpy.run_path(module, run_name="__main__")
  File "/home/nicklas/mambaforge/envs/math/lib/python3.8/runpy.py", line 265, in run_path
    return _run_module_code(code, init_globals, run_name,
  File "/home/nicklas/mambaforge/envs/math/lib/python3.8/runpy.py", line 97, in _run_module_code
    _run_code(code, mod_globals, init_globals,
  File "/home/nicklas/mambaforge/envs/math/lib/python3.8/runpy.py", line 87, in _run_code
    exec(code, run_globals)
  File "/home/nicklas/.vscode/extensions/ms-python.python-2023.6.1/pythonFiles/testing_tools/run_adapter.py", line 17, in <module>
    from testing_tools.adapter.__main__ import parse_args, main
  File "/home/nicklas/.vscode/extensions/ms-python.python-2023.6.1/pythonFiles/testing_tools/adapter/__main__.py", line 9, in <module>
    from . import pytest, report
  File "/home/nicklas/.vscode/extensions/ms-python.python-2023.6.1/pythonFiles/testing_tools/adapter/pytest/__init__.py", line 7, in <module>
    from ._discovery import discover
  File "/home/nicklas/.vscode/extensions/ms-python.python-2023.6.1/pythonFiles/testing_tools/adapter/pytest/_discovery.py", line 8, in <module>
    import pytest
ModuleNotFoundError: No module named 'pytest'
ERROR conda.cli.main_run:execute(49): `conda run python /home/nicklas/.vscode/extensions/ms-python.python-2023.6.1/pythonFiles/get_output_via_markers.py /home/nicklas/.vscode/extensions/ms-python.python-2023.6.1/pythonFiles/testing_tools/run_adapter.py discover pytest -- --rootdir /home/nicklas/Projects/maxscience -s --cache-clear` failed. (See above for error)

    at ChildProcess.<anonymous> (/home/nicklas/.vscode/extensions/ms-python.python-2023.6.1/out/client/extension.js:2:238829)
    at Object.onceWrapper (node:events:646:26)
    at ChildProcess.emit (node:events:526:28)
    at maybeClose (node:internal/child_process:1092:16)
    at Socket.<anonymous> (node:internal/child_process:451:11)
    at Socket.emit (node:events:526:28)
    at Pipe.<anonymous> (node:net:687:12)
2023-05-04 19:01:29.446 [error] Error: Traceback (most recent call last):
  File "/home/nicklas/.vscode/extensions/ms-python.python-2023.6.1/pythonFiles/get_output_via_markers.py", line 26, in <module>
    runpy.run_path(module, run_name="__main__")
  File "/home/nicklas/mambaforge/envs/math/lib/python3.8/runpy.py", line 265, in run_path
    return _run_module_code(code, init_globals, run_name,
  File "/home/nicklas/mambaforge/envs/math/lib/python3.8/runpy.py", line 97, in _run_module_code
    _run_code(code, mod_globals, init_globals,
  File "/home/nicklas/mambaforge/envs/math/lib/python3.8/runpy.py", line 87, in _run_code
    exec(code, run_globals)
  File "/home/nicklas/.vscode/extensions/ms-python.python-2023.6.1/pythonFiles/testing_tools/run_adapter.py", line 17, in <module>
    from testing_tools.adapter.__main__ import parse_args, main
  File "/home/nicklas/.vscode/extensions/ms-python.python-2023.6.1/pythonFiles/testing_tools/adapter/__main__.py", line 9, in <module>
    from . import pytest, report
  File "/home/nicklas/.vscode/extensions/ms-python.python-2023.6.1/pythonFiles/testing_tools/adapter/pytest/__init__.py", line 7, in <module>
    from ._discovery import discover
  File "/home/nicklas/.vscode/extensions/ms-python.python-2023.6.1/pythonFiles/testing_tools/adapter/pytest/_discovery.py", line 8, in <module>
    import pytest
ModuleNotFoundError: No module named 'pytest'
ERROR conda.cli.main_run:execute(49): `conda run python /home/nicklas/.vscode/extensions/ms-python.python-2023.6.1/pythonFiles/get_output_via_markers.py /home/nicklas/.vscode/extensions/ms-python.python-2023.6.1/pythonFiles/testing_tools/run_adapter.py discover pytest -- --rootdir /home/nicklas/Projects/maxscience -s --cache-clear` failed. (See above for error)

    at ChildProcess.<anonymous> (/home/nicklas/.vscode/extensions/ms-python.python-2023.6.1/out/client/extension.js:2:238829)
    at Object.onceWrapper (node:events:646:26)
    at ChildProcess.emit (node:events:526:28)
    at maybeClose (node:internal/child_process:1092:16)
    at Process.ChildProcess._handle.onexit (node:internal/child_process:302:5)
2023-05-04 19:01:30.295 [info] ExtensionService#_doActivateExtension vscode.npm, startup: false, activationEvent: 'onTerminalQuickFixRequest:ms-vscode.npm-command'
2023-05-04 19:03:47.083 [error] Error: Traceback (most recent call last):
  File "/home/nicklas/.vscode/extensions/ms-python.python-2023.6.1/pythonFiles/get_output_via_markers.py", line 26, in <module>
    runpy.run_path(module, run_name="__main__")
  File "/home/nicklas/mambaforge/envs/math/lib/python3.8/runpy.py", line 265, in run_path
    return _run_module_code(code, init_globals, run_name,
  File "/home/nicklas/mambaforge/envs/math/lib/python3.8/runpy.py", line 97, in _run_module_code
    _run_code(code, mod_globals, init_globals,
  File "/home/nicklas/mambaforge/envs/math/lib/python3.8/runpy.py", line 87, in _run_code
    exec(code, run_globals)
  File "/home/nicklas/.vscode/extensions/ms-python.python-2023.6.1/pythonFiles/testing_tools/run_adapter.py", line 17, in <module>
    from testing_tools.adapter.__main__ import parse_args, main
  File "/home/nicklas/.vscode/extensions/ms-python.python-2023.6.1/pythonFiles/testing_tools/adapter/__main__.py", line 9, in <module>
    from . import pytest, report
  File "/home/nicklas/.vscode/extensions/ms-python.python-2023.6.1/pythonFiles/testing_tools/adapter/pytest/__init__.py", line 7, in <module>
    from ._discovery import discover
  File "/home/nicklas/.vscode/extensions/ms-python.python-2023.6.1/pythonFiles/testing_tools/adapter/pytest/_discovery.py", line 8, in <module>
    import pytest
ModuleNotFoundError: No module named 'pytest'
ERROR conda.cli.main_run:execute(49): `conda run python /home/nicklas/.vscode/extensions/ms-python.python-2023.6.1/pythonFiles/get_output_via_markers.py /home/nicklas/.vscode/extensions/ms-python.python-2023.6.1/pythonFiles/testing_tools/run_adapter.py discover pytest -- --rootdir /home/nicklas/Projects/maxscience -s --cache-clear` failed. (See above for error)

    at ChildProcess.<anonymous> (/home/nicklas/.vscode/extensions/ms-python.python-2023.6.1/out/client/extension.js:2:238829)
    at Object.onceWrapper (node:events:646:26)
    at ChildProcess.emit (node:events:526:28)
    at maybeClose (node:internal/child_process:1092:16)
    at Socket.<anonymous> (node:internal/child_process:451:11)
    at Socket.emit (node:events:526:28)
    at Pipe.<anonymous> (node:net:687:12)
